<sdf version='1.7'>
  <model name='B_kubot'>
  
   <joint name="world_j" type="fixed">
      <parent>world</parent>
      <child>base_link</child>
    </joint>   
  
    <link name='base_link'>
      <inertial>
        <pose>-0 -0 0 0 -0 0</pose>
        <mass>1.186</mass>
        <inertia>
          <ixx>0.00098526</ixx>
          <ixy>0</ixy>
          <ixz>0</ixz>
          <iyy>0.00082381</iyy>
          <iyz>0</iyz>
          <izz>0.0015446</izz>
        </inertia>
      </inertial>
      <!-- <collision name='base_link_collision'>
        <pose>0 0 0 0 -0 0</pose>
        <geometry>
          <mesh>
            <scale>1 1 1</scale>
            <uri>model://B_kubot/meshes/base_link.STL</uri>
          </mesh>
        </geometry>
      </collision> -->
      <visual name='base_link_visual'>
        <pose>0 0 0 0 -0 0</pose>
        <geometry>
          <mesh>
            <scale>1 1 1</scale>
            <uri>model://B_kubot/meshes/base_link.STL</uri>
          </mesh>
        </geometry>
        <material>
         <ambient>255 255 255 1</ambient>
         <diffuse>1 1 1 1</diffuse>
         <emissive>0 0 0 1</emissive>
         <specular>0 0 0 0</specular>
        </material>
      </visual>
      
      <sensor name='IMU' type="imu">
    	<pose relative_to='base_link'>-0 -0 0 0 -0 0</pose>
    	<imu>
    	<angular_velocity>
    		<x> <noise type='none'> </noise> </x>
    		<y> <noise type='none'> </noise> </y>    
    		<z> <noise type='none'> </noise> </z>
    	</angular_velocity>
    	
    	<linear_acceleration>
    		<x> <noise type='none'> </noise> </x>
    		<y> <noise type='none'> </noise> </y>    
    		<z> <noise type='none'> </noise> </z>
    	</linear_acceleration>
    	</imu>
    	<always_on>1</always_on>
    	<update_rate>1000</update_rate>
    	<visualize>true</visualize>
    	</sensor>      
      
    </link>
    
    
    <joint name='L_Hip_yaw_joint' type='revolute'>
      <pose relative_to='base_link'>0.0235 0.049953 -0.10464 0 -0 0</pose>
      <parent>base_link</parent>
      <child>LP_Link</child>
      <axis>
        <xyz>0 0 1</xyz>
        <limit>
          <lower>0</lower>
          <upper>0</upper>
          <effort>0</effort>
          <velocity>0</velocity>
        </limit>
        <dynamics>
          <spring_reference>0</spring_reference>
          <spring_stiffness>0</spring_stiffness>
        </dynamics>
      </axis>
    </joint>
    <link name='L_Hip_yaw'>
      <pose relative_to='L_Hip_yaw_joint'>0 0 0 0 -0 0</pose>
      <inertial>
        <pose>0.009874 0 0.034357 0 -0 0</pose>
        <mass>0.056</mass>
        <inertia>
          <ixx>2.6496e-05</ixx>
          <ixy>0</ixy>
          <ixz>0</ixz>
          <iyy>3.4893e-05</iyy>
          <iyz>0</iyz>
          <izz>1.3648e-05</izz>
        </inertia>
      </inertial>
      <!-- <collision name='L_Hip_yaw_collision'>
        <pose>0 0 0 0 -0 0</pose>
        <geometry>
          <mesh>
            <scale>1 1 1</scale>
            <uri>model://B_kubot/meshes/L_Hip_yaw.STL</uri>
          </mesh>
        </geometry>
      </collision> -->
      <visual name='L_Hip_yaw_visual'>
        <pose>0 0 0 0 -0 0</pose>
        <geometry>
          <mesh>
            <scale>1 1 1</scale>
            <uri>model://B_kubot/meshes/L_Hip_yaw.STL</uri>
          </mesh>
        </geometry>
      </visual>
    </link>
    <joint name='L_Hip_roll_joint' type='revolute'>
      <pose relative_to='L_Hip_yaw'>0 0 0 0 -0 0</pose>
      <parent>L_Hip_yaw</parent>
      <child>L_Hip_roll</child>
      <axis>
        <xyz>1 0 0</xyz>
        <limit>
          <lower>0</lower>
          <upper>0</upper>
          <effort>0</effort>
          <velocity>0</velocity>
        </limit>
        <dynamics>
          <spring_reference>0</spring_reference>
          <spring_stiffness>0</spring_stiffness>
        </dynamics>
      </axis>
    </joint>
    <link name='L_Hip_roll'>
      <pose relative_to='L_Hip_roll_joint'>0 0 0 0 -0 0</pose>
      <inertial>
        <pose>-0.025734 3.9e-05 -0.015188 0 -0 0</pose>
        <mass>0.185</mass>
        <inertia>
          <ixx>5.7097e-05</ixx>
          <ixy>0</ixy>
          <ixz>0</ixz>
          <iyy>5.645e-05</iyy>
          <iyz>0</iyz>
          <izz>3.5595e-05</izz>
        </inertia>
      </inertial>
      <!-- <collision name='L_Hip_roll_collision'>
        <pose>0 0 0 0 -0 0</pose>
        <geometry>
          <mesh>
            <scale>1 1 1</scale>
            <uri>model://B_kubot/meshes/L_Hip_roll.STL</uri>
          </mesh>
        </geometry>
      </collision> -->
      <visual name='L_Hip_roll_visual'>
        <pose>0 0 0 0 -0 0</pose>
        <geometry>
          <mesh>
            <scale>1 1 1</scale>
            <uri>model://B_kubot/meshes/L_Hip_roll.STL</uri>
          </mesh>
        </geometry>
      </visual>
    </link>
    <joint name='L_Hip_pitch_joint' type='revolute'>
      <pose relative_to='L_Hip_roll'>0 0 0 0 -0 0</pose>
      <parent>L_Hip_roll</parent>
      <child>L_Hip_pitch</child>
      <axis>
        <xyz>0 1 0</xyz>
        <limit>
          <lower>0</lower>
          <upper>0</upper>
          <effort>0</effort>
          <velocity>0</velocity>
        </limit>
        <dynamics>
          <spring_reference>0</spring_reference>
          <spring_stiffness>0</spring_stiffness>
        </dynamics>
      </axis>
    </joint>
    <link name='L_Hip_pitch'>
      <pose relative_to='L_Hip_pitch_joint'>0 0 0 0 -0 0</pose>
      <inertial>
        <pose>2e-06 0.000169 -0.096826 0 -0 0</pose>
        <mass>0.304</mass>
        <inertia>
          <ixx>0.00012605</ixx>
          <ixy>0</ixy>
          <ixz>0</ixz>
          <iyy>9.2705e-05</iyy>
          <iyz>0</iyz>
          <izz>6.2851e-05</izz>
        </inertia>
      </inertial>
      <!-- <collision name='L_Hip_pitch_collision'>
        <pose>0 0 0 0 -0 0</pose>
        <geometry>
          <mesh>
            <scale>1 1 1</scale>
            <uri>model://B_kubot/meshes/L_Hip_pitch.STL</uri>
          </mesh>
        </geometry>
      </collision> -->
      <visual name='L_Hip_pitch_visual'>
        <pose>0 0 0 0 -0 0</pose>
        <geometry>
          <mesh>
            <scale>1 1 1</scale>
            <uri>model://B_kubot/meshes/L_Hip_pitch.STL</uri>
          </mesh>
        </geometry>
      </visual>
    </link>
    <joint name='L_Knee_joint' type='revolute'>
      <pose relative_to='L_Hip_pitch'>-0.00032 0 -0.138 0 -0 0</pose>
      <parent>L_Hip_pitch</parent>
      <child>L_Knee</child>
      <axis>
        <xyz>0 1 0</xyz>
        <limit>
          <lower>0</lower>
          <upper>0</upper>
          <effort>0</effort>
          <velocity>0</velocity>
        </limit>
        <dynamics>
          <spring_reference>0</spring_reference>
          <spring_stiffness>0</spring_stiffness>
        </dynamics>
      </axis>
    </joint>
    <link name='L_Knee'>
      <pose relative_to='L_Knee_joint'>0 0 0 0 -0 0</pose>
      <inertial>
        <pose>0.002471 0.0002 -0.064983 0 -0 0</pose>
        <mass>0.053</mass>
        <inertia>
          <ixx>0.00012155</ixx>
          <ixy>0</ixy>
          <ixz>0</ixz>
          <iyy>9.3136e-05</iyy>
          <iyz>0</iyz>
          <izz>3.7874e-05</izz>
        </inertia>
      </inertial>
      <!-- <collision name='L_Knee_collision'>
        <pose>0 0 0 0 -0 0</pose>
        <geometry>
          <mesh>
            <scale>1 1 1</scale>
            <uri>model://B_kubot/meshes/L_Knee.STL</uri>
          </mesh>
        </geometry>
      </collision> -->
      <visual name='L_Knee_visual'>
        <pose>0 0 0 0 -0 0</pose>
        <geometry>
          <mesh>
            <scale>1 1 1</scale>
            <uri>model://B_kubot/meshes/L_Knee.STL</uri>
          </mesh>
        </geometry>
      </visual>
    </link>
    <joint name='L_Ankle_pitch_joint' type='revolute'>
      <pose relative_to='L_Knee'>0.00032 0.0001 -0.143 0 -0 0</pose>
      <parent>L_Knee</parent>
      <child>L_Ankle_pitch</child>
      <axis>
        <xyz>0 1 0</xyz>
        <limit>
          <lower>0</lower>
          <upper>0</upper>
          <effort>0</effort>
          <velocity>0</velocity>
        </limit>
        <dynamics>
          <spring_reference>0</spring_reference>
          <spring_stiffness>0</spring_stiffness>
        </dynamics>
      </axis>
    </joint>
    <link name='L_Ankle_pitch'>
      <pose relative_to='L_Ankle_pitch_joint'>0 0 0 0 -0 0</pose>
      <inertial>
        <pose>-0.024331 5.1e-05 0.014723 0 -0 0</pose>
        <mass>0.229</mass>
        <inertia>
          <ixx>7.8092e-05</ixx>
          <ixy>0</ixy>
          <ixz>0</ixz>
          <iyy>7.7114e-05</iyy>
          <iyz>0</iyz>
          <izz>4.8232e-05</izz>
        </inertia>
      </inertial>
      <!-- <collision name='L_Ankle_pitch_collision'>
        <pose>0 0 0 0 -0 0</pose>
        <geometry>
          <mesh>
            <scale>1 1 1</scale>
            <uri>model://B_kubot/meshes/L_Ankle_pitch.STL</uri>
          </mesh>
        </geometry>
      </collision> -->
      <visual name='L_Ankle_pitch_visual'>
        <pose>0 0 0 0 -0 0</pose>
        <geometry>
          <mesh>
            <scale>1 1 1</scale>
            <uri>model://B_kubot/meshes/L_Ankle_pitch.STL</uri>
          </mesh>
        </geometry>
      </visual>
    </link>
    <joint name='L_Ankle_roll_joint' type='revolute'>
      <pose relative_to='L_Ankle_pitch'>0 0 0 0 -0 0</pose>
      <parent>L_Ankle_pitch</parent>
      <child>L_Ankle_roll</child>
      <axis>
        <xyz>1 0 0</xyz>
        <limit>
          <lower>0</lower>
          <upper>0</upper>
          <effort>0</effort>
          <velocity>0</velocity>
        </limit>
        <dynamics>
          <spring_reference>0</spring_reference>
          <spring_stiffness>0</spring_stiffness>
        </dynamics>
      </axis>
    </joint>
    <link name='L_Ankle_roll'>
      <pose relative_to='L_Ankle_roll_joint'>0 0 0 0 -0 0</pose>
      <inertial>
        <pose>-0.029387 -0 -0.015903 0 -0 0</pose>
        <mass>0.016</mass>
        <inertia>
          <ixx>1.6806e-06</ixx>
          <ixy>0</ixy>
          <ixz>0</ixz>
          <iyy>1.3489e-06</iyy>
          <iyz>0</iyz>
          <izz>4.405e-07</izz>
        </inertia>
      </inertial>
      <!-- <collision name='L_Ankle_roll_collision'>
        <pose>0 0 0 0 -0 0</pose>
        <geometry>
          <mesh>
            <scale>1 1 1</scale>
            <uri>model://B_kubot/meshes/L_Ankle_roll.STL</uri>
          </mesh>
        </geometry>
      </collision> -->
      <visual name='L_Ankle_roll_visual'>
        <pose>0 0 0 0 -0 0</pose>
        <geometry>
          <mesh>
            <scale>1 1 1</scale>
            <uri>model://B_kubot/meshes/L_Ankle_roll.STL</uri>
          </mesh>
        </geometry>
      </visual>
    </link>
    <joint name='L_Foot_joint' type='revolute'>
      <pose relative_to='L_Ankle_roll'>-0.00032 -0.0001 -0.04 0 -0 0</pose>
      <parent>L_Ankle_roll</parent>
      <child>L_Foot</child>
    </joint>
    <link name='L_Foot'>
      <pose relative_to='L_Foot_joint'>0 0 0 0 -0 0</pose>
      <inertial>
        <pose>0.000978 0.016837 0.002503 0 -0 0</pose>
        <mass>0.2</mass>
        <inertia>
          <ixx>6.1573e-05</ixx>
          <ixy>0</ixy>
          <ixz>0</ixz>
          <iyy>0.00013809</iyy>
          <iyz>0</iyz>
          <izz>0.00019935</izz>
        </inertia>
      </inertial>
      <collision name='L_Foot_collision'>
        <pose>0.00095 0.017 0.0015 0 -0 0</pose>
        <geometry>
	 <box>
	 <size>0.15 0.1 0.007</size>
	 </box> 
          <!-- <mesh>
            <scale>1 1 1</scale>
            <uri>model://B_kubot/meshes/L_Foot.STL</uri>
          </mesh> -->
        </geometry>
      </collision>
      <visual name='L_Foot_visual'>
        <pose>0 0 0 0 -0 0</pose>
        <geometry>
          <mesh>
            <scale>1 1 1</scale>
            <uri>model://B_kubot/meshes/L_Foot.STL</uri>
          </mesh>
        </geometry>
      </visual>
    </link>
    <joint name='R_Hip_yaw_joint' type='revolute'>
      <pose relative_to='base_link'>0.0235 -0.050047 -0.10464 0 -0 0</pose>
      <parent>base_link</parent>
      <child>R_Hip_yaw</child>
      <axis>
        <xyz>0 0 1</xyz>
        <limit>
          <lower>0</lower>
          <upper>0</upper>
          <effort>0</effort>
          <velocity>0</velocity>
        </limit>
        <dynamics>
          <spring_reference>0</spring_reference>
          <spring_stiffness>0</spring_stiffness>
        </dynamics>
      </axis>
    </joint>
    <link name='R_Hip_yaw'>
      <pose relative_to='R_Hip_yaw_joint'>0 0 0 0 -0 0</pose>
      <inertial>
        <pose>0.009874 -0 0.034357 0 -0 0</pose>
        <mass>0.056</mass>
        <inertia>
          <ixx>2.6496e-05</ixx>
          <ixy>0</ixy>
          <ixz>0</ixz>
          <iyy>3.4893e-05</iyy>
          <iyz>0</iyz>
          <izz>1.3648e-05</izz>
        </inertia>
      </inertial>
      <!-- <collision name='R_Hip_yaw_collision'>
        <pose>0 0 0 0 -0 0</pose>
        <geometry>
          <mesh>
            <scale>1 1 1</scale>
            <uri>model://B_kubot/meshes/R_Hip_yaw.STL</uri>
          </mesh>
        </geometry>
      </collision> -->
      <visual name='R_Hip_yaw_visual'>
        <pose>0 0 0 0 -0 0</pose>
        <geometry>
          <mesh>
            <scale>1 1 1</scale>
            <uri>model://B_kubot/meshes/R_Hip_yaw.STL</uri>
          </mesh>
        </geometry>
      </visual>
    </link>
    <joint name='R_Hip_roll_joint' type='revolute'>
      <pose relative_to='R_Hip_yaw'>0 0 0 0 -0 0</pose>
      <parent>R_Hip_yaw</parent>
      <child>R_Hip_roll</child>
      <axis>
        <xyz>1 0 0</xyz>
        <limit>
          <lower>0</lower>
          <upper>0</upper>
          <effort>0</effort>
          <velocity>0</velocity>
        </limit>
        <dynamics>
          <spring_reference>0</spring_reference>
          <spring_stiffness>0</spring_stiffness>
        </dynamics>
      </axis>
    </joint>
    <link name='R_Hip_roll'>
      <pose relative_to='R_Hip_roll_joint'>0 0 0 0 -0 0</pose>
      <inertial>
        <pose>-0.025734 -3.9e-05 -0.015188 0 -0 0</pose>
        <mass>0.185</mass>
        <inertia>
          <ixx>5.7097e-05</ixx>
          <ixy>0</ixy>
          <ixz>0</ixz>
          <iyy>5.645e-05</iyy>
          <iyz>0</iyz>
          <izz>3.5595e-05</izz>
        </inertia>
      </inertial>
      <!-- <collision name='R_Hip_roll_collision'>
        <pose>0 0 0 0 -0 0</pose>
        <geometry>
          <mesh>
            <scale>1 1 1</scale>
            <uri>model://B_kubot/meshes/R_Hip_roll.STL</uri>
          </mesh>
        </geometry>
      </collision> -->
      <visual name='R_Hip_roll_visual'>
        <pose>0 0 0 0 -0 0</pose>
        <geometry>
          <mesh>
            <scale>1 1 1</scale>
            <uri>model://B_kubot/meshes/R_Hip_roll.STL</uri>
          </mesh>
        </geometry>
      </visual>
    </link>
    <joint name='R_Hip_pitch_joint' type='revolute'>
      <pose relative_to='R_Hip_roll'>0 0 0 0 -0 0</pose>
      <parent>R_Hip_roll</parent>
      <child>R_Hip_pitch</child>
      <axis>
        <xyz>0 1 0</xyz>
        <limit>
          <lower>0</lower>
          <upper>0</upper>
          <effort>0</effort>
          <velocity>0</velocity>
        </limit>
        <dynamics>
          <spring_reference>0</spring_reference>
          <spring_stiffness>0</spring_stiffness>
        </dynamics>
      </axis>
    </joint>
    <link name='R_Hip_pitch'>
      <pose relative_to='R_Hip_pitch_joint'>0 0 0 0 -0 0</pose>
      <inertial>
        <pose>-2e-06 -0.000169 -0.096826 0 -0 0</pose>
        <mass>0.304</mass>
        <inertia>
          <ixx>0.00012605</ixx>
          <ixy>0</ixy>
          <ixz>0</ixz>
          <iyy>9.2705e-05</iyy>
          <iyz>0</iyz>
          <izz>6.2851e-05</izz>
        </inertia>
      </inertial>
      <!-- <collision name='R_Hip_pitch_collision'>
        <pose>0 0 0 0 -0 0</pose>
        <geometry>
          <mesh>
            <scale>1 1 1</scale>
            <uri>model://B_kubot/meshes/R_Hip_pitch.STL</uri>
          </mesh>
        </geometry>
      </collision> -->
      <visual name='R_Hip_pitch_visual'>
        <pose>0 0 0 0 -0 0</pose>
        <geometry>
          <mesh>
            <scale>1 1 1</scale>
            <uri>model://B_kubot/meshes/R_Hip_pitch.STL</uri>
          </mesh>
        </geometry>
      </visual>
    </link>
    <joint name='R_Knee_joint' type='revolute'>
      <pose relative_to='R_Hip_pitch'>-0.00032 0 -0.138 0 -0 0</pose>
      <parent>R_Hip_pitch</parent>
      <child>R_Knee</child>
      <axis>
        <xyz>0 1 0</xyz>
        <limit>
          <lower>0</lower>
          <upper>0</upper>
          <effort>0</effort>
          <velocity>0</velocity>
        </limit>
        <dynamics>
          <spring_reference>0</spring_reference>
          <spring_stiffness>0</spring_stiffness>
        </dynamics>
      </axis>
    </joint>
    <link name='R_Knee'>
      <pose relative_to='R_Knee_joint'>0 0 0 0 -0 0</pose>
      <inertial>
        <pose>0.002471 -0.0002 -0.064983 0 -0 0</pose>
        <mass>0.053</mass>
        <inertia>
          <ixx>0.00012155</ixx>
          <ixy>0</ixy>
          <ixz>0</ixz>
          <iyy>9.3136e-05</iyy>
          <iyz>0</iyz>
          <izz>3.7874e-05</izz>
        </inertia>
      </inertial>
      <!-- <collision name='R_Knee_collision'>
        <pose>0 0 0 0 -0 0</pose>
        <geometry>
          <mesh>
            <scale>1 1 1</scale>
            <uri>model://B_kubot/meshes/R_Knee.STL</uri>
          </mesh>
        </geometry>
      </collision> -->
      <visual name='R_Knee_visual'>
        <pose>0 0 0 0 -0 0</pose>
        <geometry>
          <mesh>
            <scale>1 1 1</scale>
            <uri>model://B_kubot/meshes/R_Knee.STL</uri>
          </mesh>
        </geometry>
      </visual>
    </link>
    <joint name='R_Ankle_pitch_joint' type='revolute'>
      <pose relative_to='R_Knee'>0.00032 -0.0001 -0.143 0 -0 0</pose>
      <parent>R_Knee</parent>
      <child>R_Ankle_pitch</child>
      <axis>
        <xyz>0 1 0</xyz>
        <limit>
          <lower>0</lower>
          <upper>0</upper>
          <effort>0</effort>
          <velocity>0</velocity>
        </limit>
        <dynamics>
          <spring_reference>0</spring_reference>
          <spring_stiffness>0</spring_stiffness>
        </dynamics>
      </axis>
    </joint>
    <link name='R_Ankle_pitch'>
      <pose relative_to='R_Ankle_pitch_joint'>0 0 0 0 -0 0</pose>
      <inertial>
        <pose>-0.024334 -5.4e-05 0.014723 0 -0 0</pose>
        <mass>0.229</mass>
        <inertia>
          <ixx>7.8092e-05</ixx>
          <ixy>0</ixy>
          <ixz>0</ixz>
          <iyy>7.7114e-05</iyy>
          <iyz>0</iyz>
          <izz>4.8232e-05</izz>
        </inertia>
      </inertial>
      <!-- <collision name='R_Ankle_pitch_collision'>
        <pose>0 0 0 0 -0 0</pose>
        <geometry>
          <mesh>
            <scale>1 1 1</scale>
            <uri>model://B_kubot/meshes/R_Ankle_pitch.STL</uri>
          </mesh>
        </geometry>
      </collision> -->
      <visual name='R_Ankle_pitch_visual'>
        <pose>0 0 0 0 -0 0</pose>
        <geometry>
          <mesh>
            <scale>1 1 1</scale>
            <uri>model://B_kubot/meshes/R_Ankle_pitch.STL</uri>
          </mesh>
        </geometry>
      </visual>
    </link>
    <joint name='R_Ankle_roll_joint' type='revolute'>
      <pose relative_to='R_Ankle_pitch'>0 0 0 0 -0 0</pose>
      <parent>R_Ankle_pitch</parent>
      <child>R_Ankle_roll</child>
      <axis>
        <xyz>1 0 0</xyz>
        <limit>
          <lower>0</lower>
          <upper>0</upper>
          <effort>0</effort>
          <velocity>0</velocity>
        </limit>
        <dynamics>
          <spring_reference>0</spring_reference>
          <spring_stiffness>0</spring_stiffness>
        </dynamics>
      </axis>
    </joint>
    <link name='R_Ankle_roll'>
      <pose relative_to='R_Ankle_roll_joint'>0 0 0 0 -0 0</pose>
      <inertial>
        <pose>-0.029387 -0 -0.015903 0 -0 0</pose>
        <mass>0.016</mass>
        <inertia>
          <ixx>1.6806e-06</ixx>
          <ixy>0</ixy>
          <ixz>0</ixz>
          <iyy>1.3489e-06</iyy>
          <iyz>0</iyz>
          <izz>4.405e-07</izz>
        </inertia>
      </inertial>
      <!-- <collision name='R_Ankle_roll_collision'>
        <pose>0 0 0 0 -0 0</pose>
        <geometry>
          <mesh>
            <scale>1 1 1</scale>
            <uri>model://B_kubot/meshes/R_Ankle_roll.STL</uri>
          </mesh>
        </geometry>
      </collision> -->
      <visual name='R_Ankle_roll_visual'>
        <pose>0 0 0 0 -0 0</pose>
        <geometry>
          <mesh>
            <scale>1 1 1</scale>
            <uri>model://B_kubot/meshes/R_Ankle_roll.STL</uri>
          </mesh>
        </geometry>
      </visual>
    </link>
    <joint name='R_Foot_joint' type='revolute'>
      <pose relative_to='R_Ankle_roll'>-0.00032 0.0001 -0.04 0 -0 0</pose>
      <parent>R_Ankle_roll</parent>
      <child>R_Foot</child>
      <axis>
        <xyz>0 0 1</xyz>
        <limit>
          <lower>0</lower>
          <upper>0</upper>
          <effort>0</effort>
          <velocity>0</velocity>
        </limit>
        <dynamics>
          <spring_reference>0</spring_reference>
          <spring_stiffness>0</spring_stiffness>
        </dynamics>
      </axis>
    </joint>
    <link name='R_Foot'>
      <pose relative_to='R_Foot_joint'>0 0 0 0 -0 0</pose>
      <inertial>
        <pose>0.001922 -0.016829 0.002503 0 -0 0</pose>
        <mass>0.201</mass>
        <inertia>
          <ixx>6.1584e-05</ixx>
          <ixy>0</ixy>
          <ixz>0</ixz>
          <iyy>0.00013813</iyy>
          <iyz>0</iyz>
          <izz>0.00019941</izz>
        </inertia>
      </inertial>
      <collision name='R_Foot_collision'>
        <pose>0.00095 -0.017 0.0015 0 -0 0</pose>
        <geometry>
	 <box>
	 <size>0.15 0.1 0.007</size>
	 </box>  
          <!-- <mesh>
            <scale>1 1 1</scale>
            <uri>model://B_kubot/meshes/R_Foot.STL</uri>
          </mesh> -->
        </geometry>
      </collision>
      <visual name='R_Foot_visual'>
        <pose>0 0 0 0 -0 0</pose>
        <geometry>
          <mesh>
            <scale>1 1 1</scale>
            <uri>model://B_kubot/meshes/R_Foot.STL</uri>
          </mesh>
        </geometry>
      </visual>
    </link>
  </model>
</sdf>
